Workbook

Sheet Calculator
A1: Educational tool, not financial, tax or legal advice. It models a matching formula and a vesting schedule. Your own plan document is the only place that states yours. 2026 limits.
A3: YOUR NUMBERS
A4: Annual salary | C4: 91000 | D4: ← fill every amber cell
A5: Paychecks per year | C5: 26
A6: Your contribution rate | C6: 0.05
A7: Years of service | C7: 3 | D7: used by the vesting tab below
A9: YOUR PLAN'S FORMULA
A10: Tier 1 — matched up to this much of pay | C10: 0.03 | D10: defaults = the basic safe harbor match described by the IRS
A11: Tier 1 — matched at this rate | C11: 1
A12: Tier 2 — next slice of pay | C12: 0.02 | D12: set tier 2 to 0% if your plan has a single tier
A13: Tier 2 — matched at this rate | C13: 0.5
A15: Match computed | C15: per paycheck | D15: type "per paycheck" or "annual" — your plan document says which
A17: WHAT THE FORMULA ACTUALLY PAYS
A18: Contribution needed to reach the ceiling | C18: =$C$10+$C$12
A19: Match ceiling, as a share of pay | C19: =$C$10*$C$11+$C$12*$C$13 | D19: ← these two are NOT the same number
A21: Your match rate at your contribution rate | C21: =MIN($C$6,$C$10)*$C$11+MIN(MAX($C$6-$C$10,0),$C$12)*$C$13 | D21: flat once you pass the ceiling: more contribution, same match
A23: PER PAYCHECK
A24: Gross pay per paycheck | C24: =$C$4/$C$5
A25: You contribute | C25: =$C$24*$C$6
A26: Employer matches | C26: =$C$24*$C$21
A28: OVER THE YEAR
A29: Paycheck on which you hit the annual limit | C29: =IF($C$25<=0,$C$5,MIN($C$5,ROUNDUP(Rates!$B$4/$C$25,0))) | D29: if this is below your paycheck count, read the next two lines
A30: Paychecks with no contribution left | C30: =MAX(0,$C$5-$C$29)
A31: Match if computed ANNUALLY (or trued up) | C31: =MIN($C$4,Rates!$B$8)*$C$21
A32: Match if computed PER PAYCHECK | C32: =$C$26*$C$29
A33: What the per paycheck computation costs you | C33: =MAX(0,$C$31-$C$32) | D33: zero if you spread contributions across every paycheck
A34: Match actually used by the rest of this file | C34: =IF(LOWER($C$15)="annual",$C$31,$C$32)
A36: HOW MUCH OF THE MATCH IS ALREADY YOURS
B37: 3-year cliff | D37: 6-year graded
A38: Vested share at your years of service | B38: =IF($C$7>=Rates!$B$12,1,0) | D38: =LOOKUP(MIN($C$7,6),Rates!$F$12:$F$18,Rates!$G$12:$G$18)
A39: Vested dollars from this year's match | B39: =$C$34*$B$38 | D39: =$C$34*$D$38
A41: These are the LONGEST schedules a plan may use (IRC 411(a)(2)(B)). A plan may vest faster, including immediately. In a safe harbor plan, required employer contributions are 100% vested at all times.
A43: WHAT YOU GET AT EVERY CONTRIBUTION RATE
A44: You contribute | B44: Employer match rate | C44: Your dollars / year | D44: Match dollars / year
A45: 0 | B45: =MIN($A45,$C$10)*$C$11+MIN(MAX($A45-$C$10,0),$C$12)*$C$13 | C45: =MIN($A45*$C$4,Rates!$B$4) | D45: =MIN($C$4,Rates!$B$8)*$B45
A46: 0.01 | B46: =MIN($A46,$C$10)*$C$11+MIN(MAX($A46-$C$10,0),$C$12)*$C$13 | C46: =MIN($A46*$C$4,Rates!$B$4) | D46: =MIN($C$4,Rates!$B$8)*$B46
A47: 0.02 | B47: =MIN($A47,$C$10)*$C$11+MIN(MAX($A47-$C$10,0),$C$12)*$C$13 | C47: =MIN($A47*$C$4,Rates!$B$4) | D47: =MIN($C$4,Rates!$B$8)*$B47
A48: 0.03 | B48: =MIN($A48,$C$10)*$C$11+MIN(MAX($A48-$C$10,0),$C$12)*$C$13 | C48: =MIN($A48*$C$4,Rates!$B$4) | D48: =MIN($C$4,Rates!$B$8)*$B48
A49: 0.04 | B49: =MIN($A49,$C$10)*$C$11+MIN(MAX($A49-$C$10,0),$C$12)*$C$13 | C49: =MIN($A49*$C$4,Rates!$B$4) | D49: =MIN($C$4,Rates!$B$8)*$B49
A50: 0.05 | B50: =MIN($A50,$C$10)*$C$11+MIN(MAX($A50-$C$10,0),$C$12)*$C$13 | C50: =MIN($A50*$C$4,Rates!$B$4) | D50: =MIN($C$4,Rates!$B$8)*$B50
...

Sheet Rates
A1: 2026 LIMITS — all annual, all from the IRS
A4: Elective deferral limit | B4: 24500 | C4: IRC 402(g)(1)
A5: Catch-up, age 50 and over | B5: 8000 | C5: IRC 414(v)
A6: Catch-up, ages 60 to 63 | B6: 11250 | C6: SECURE 2.0
A7: Total annual additions | B7: 72000 | C7: IRC 415(c)(1)(A)
A8: Compensation a match may be computed on | B8: 360000 | C8: IRC 401(a)(17)
A10: VESTING — the longest schedules a plan may use
A11: Cliff: full vesting after this many years | F11: Years | G11: Vested
A12: years of service | B12: 3 | F12: 0 | G12: 0
F13: 1 | G13: 0
F14: 2 | G14: 0.2
F15: 3 | G15: 0.4
F16: 4 | G16: 0.6
F17: 5 | G17: 0.8
F18: 6 | G18: 1
F19: IRC 411(a)(2)(B) — a plan may vest faster
A21: THE FORMULA USED BY DEFAULT
A22: "Under a safe harbor plan, you can match each eligible employee's contribution, dollar-for-dollar, up to 3 percent of the employee's compensation, and 50 cents on the dollar for the employee's contribution that exceeds 3 percent, but not 5 percent, of the employee's compensation." — IRS, Operating a 401(k) plan
A24: These percentages are in the tax code. Unlike the dollar limits above, they do not change on January 1st.

Sheet Sources
A1: EVERY FIGURE IN THIS FILE, AND WHERE IT COMES FROM
A2: What | B2: Who | C2: Reference | D2: URL | E2: Checked
A3: Basic safe harbor match: dollar-for-dollar up to 3% of compensation, then 50 cents on the dollar above 3% but not above 5% | B3: IRS | C3: Operating a 401(k) plan | D3: https://www.irs.gov/retirement-plans/operating-a-401k-plan | E3: 2026-10-06
A4: Safe harbor required employer contributions are always 100% vested | B4: IRS | C4: Operating a 401(k) plan | D4: https://www.irs.gov/retirement-plans/operating-a-401k-plan | E4: 2026-10-06
A5: A match calculated per payroll period may not match the terms of a plan written annually | B5: IRS | C5: 401(k) fix-it guide, employer matching contributions | D5: https://www.irs.gov/retirement-plans/401k-plan-fix-it-guide-employer-matching-contributions-werent-made-to-all-appropriate-employees | E5: 2026-10-06
A6: Longest vesting schedules a plan may use: 3-year cliff, or 6-year graded 20/40/60/80/100 | B6: IRS | C6: Issue Snapshot, vesting schedules (IRC 411(a)(2)(B)) | D6: https://www.irs.gov/retirement-plans/issue-snapshot-vesting-schedules-for-matching-contributions | E6: 2026-10-06
A7: 2026 elective deferral limit $24,500, catch-up $8,000, ages 60-63 $11,250 | B7: IRS | C7: IR-2025-111 / Notice 2025-67 | D7: https://www.irs.gov/newsroom/401k-limit-increases-to-24500-for-2026-ira-limit-increases-to-7500 | E7: 2026-10-06
A8: 2026 total annual additions limit $72,000 (IRC 415(c)) and compensation limit $360,000 (IRC 401(a)(17)) | B8: IRS | C8: COLA increases table | D8: https://www.irs.gov/retirement-plans/cola-increases-for-dollar-limitations-on-benefits-and-contributions | E8: 2026-10-06
A10: The one thing this file cannot know
A11: Your plan's own formula, its computation period, and its vesting schedule. Those three live in your summary plan description. Everything here is a default taken from what the IRS describes, not a statement about your employer.
