Workbook

Sheet Calculator
A1: Educational tool, not tax or financial advice. 2026 tax year, single filer, federal only — no state income tax. Withholding is an estimate, not your final tax.
A3: YOUR NUMBERS
A4: Gross annual salary | C4: 78000 | D4: ← fill the four amber cells
A5: Pay periods per year | C5: 26
A6: 401(k) contribution rate | C6: 0.06
A7: Health premium per paycheck | C7: 120 | D7: pre-tax, through a Section 125 plan
A9: PER PAYCHECK
A10: Gross pay | C10: =$C$4/$C$5
A11: 401(k) contribution | C11: =-$C$10*$C$6
A12: Health premium | C12: =-$C$7
A14: THE TWO TAXABLE BASES
B15: FICA base | D15: Income tax base
A16: Gross pay | B16: =$C$10 | D16: =$C$10
A17: minus health premium | B17: =-$C$7 | D17: =-$C$7
A18: minus 401(k) | B18: not deducted | D18: =$C$11
A19: =TAXABLE BASE | B19: =$B$16+$B$17 | D19: =$D$16+$D$17+$D$18
A20: Difference = your 401(k) | C20: =$B$19-$D$19 | D20: ← FICA is charged on this; income tax is not
A22: WITHHELD FROM THIS PAYCHECK
A23: Social Security (6.2% of FICA base) | C23: =-$B$19*Rates!$B$4
A24: Medicare (1.45% of FICA base) | C24: =-$B$19*Rates!$B$5
A25: Federal income tax | C25: =-$C$38/$C$5
A26: Total withheld | C26: =$C$23+$C$24+$C$25
A28: NET PAY
A29: Take-home per paycheck | C29: =$C$10+$C$11+$C$12+$C$23+$C$24+$C$25
A30: As a share of gross | C30: =IF($C$10=0,0,$C$29/$C$10)
A31: FICA paid on your 401(k), per year | C31: =-$C$11*(Rates!$B$4+Rates!$B$5)*$C$5
A33: ANNUAL — INCOME TAX WORKING
A34: Income tax base, annualised | C34: =$D$19*$C$5
A35: Standard deduction | C35: =-Rates!$B$16
A36: Taxable income | C36: =MAX(0,$C$34+$C$35)
A37: Marginal rate | C37: =IF($C$36<=0,0,INDEX(Rates!$H$4:$H$10,SUMPRODUCT(--(F41:F47>0))))
A38: Federal income tax for the year | C38: =SUM($G$41:$G$47)
E40: bracket | F40: taxed here | G40: tax
E41: =Rates!$H4 | F41: =MAX(0,MIN($C$36,Rates!$G4)-Rates!$F4) | G41: =$F41*$E41
E42: =Rates!$H5 | F42: =MAX(0,MIN($C$36,Rates!$G5)-Rates!$F5) | G42: =$F42*$E42
E43: =Rates!$H6 | F43: =MAX(0,MIN($C$36,Rates!$G6)-Rates!$F6) | G43: =$F43*$E43
E44: =Rates!$H7 | F44: =MAX(0,MIN($C$36,Rates!$G7)-Rates!$F7) | G44: =$F44*$E44
E45: =Rates!$H8 | F45: =MAX(0,MIN($C$36,Rates!$G8)-Rates!$F8) | G45: =$F45*$E45
E46: =Rates!$H9 | F46: =MAX(0,MIN($C$36,Rates!$G9)-Rates!$F9) | G46: =$F46*$E46
E47: =Rates!$H10 | F47: =MAX(0,MIN($C$36,Rates!$G10)-Rates!$F10) | G47: =$F47*$E47
...

Sheet Rates
A1: 2026 TAX YEAR — SINGLE FILER
F2: Income tax brackets (on taxable income)
A3: Payroll taxes | F3: From | G3: To | H3: Rate
A4: Social Security rate (employee) | B4: 0.062 | F4: 0 | G4: 12400 | H4: 0.1
A5: Medicare rate (employee) | B5: 0.0145 | F5: 12400 | G5: 50400 | H5: 0.12
A6: Social Security wage base | B6: 184500 | F6: 50400 | G6: 105700 | H6: 0.22
A7: Additional Medicare rate | B7: 0.009 | F7: 105700 | G7: 201775 | H7: 0.24
A8: Additional Medicare threshold | B8: 200000 | F8: 201775 | G8: 256225 | H8: 0.32
F9: 256225 | G9: 640600 | H9: 0.35
F10: 640600 | G10: 1000000000000 | H10: 0.37
A16: Standard deduction — single | B16: 16100
A18: Figures change every year. Check the Sources tab before reusing this file for another tax year.

Sheet Sources
A1: PRIMARY SOURCES — every figure in this file
A3: Item | B3: Source | C3: Reference | D3: URL | E3: Date checked
A4: 2026 Social Security rate and wage base | B4: SSA | C4: Contribution and Benefit Base | D4: https://www.ssa.gov/oact/cola/cbb.html | E4: 2026-09-15
A5: Social Security and Medicare rates, wage base, Additional Medicare tax | B5: IRS | C5: Topic no. 751 | D5: https://www.irs.gov/taxtopics/tc751 | E5: 2026-09-15
A6: 401(k) deferrals ARE subject to Social Security and Medicare | B6: IRS | C6: Topic no. 424 | D6: https://www.irs.gov/taxtopics/tc424 | E6: 2026-09-15
A7: 2026 standard deduction and tax brackets | B7: IRS | C7: IR-2025-103 / Rev. Proc. 2025-32 | D7: https://www.irs.gov/newsroom/irs-releases-tax-inflation-adjustments-for-tax-year-2026-including-amendments-from-the-one-big-beautiful-bill | E7: 2026-09-15
A8: Withholding is an estimate, not final tax | B8: IRS | C8: Publication 15-T | D8: https://www.irs.gov/pub/irs-pdf/p15t.pdf | E8: 2026-09-15
A11: Nothing here is sourced from a blog, a news site, or an AI. Every number was read on the issuing agency's own page.
